File "/usr/local/lib/python3.9/site-packages/mysql/connector/connection_cext.py", line 661, in cmd_query
    self._cmysql.query(
_mysql_connector.MySQLInterfaceError: Lost connection to MySQL server during query

The above exception was the direct cause of the following exception:

Traceback (most recent call last):
  File "/usr/local/lib/python3.9/site-packages/uvicorn/protocols/http/httptools_impl.py", line 419, in run_asgi
    result = await app(  # type: ignore[func-returns-value]
  File "/usr/local/lib/python3.9/site-packages/uvicorn/middleware/proxy_headers.py", line 78, in __call__
    return await self.app(scope, receive, send)
  File "/usr/local/lib/python3.9/site-packages/fastapi/applications.py", line 1054, in __call__
    await super().__call__(scope, receive, send)
  File "/usr/local/lib/python3.9/site-packages/starlette/applications.py", line 123, in __call__
    await self.middleware_stack(scope, receive, send)
  File "/usr/local/lib/python3.9/site-packages/starlette/middleware/errors.py", line 186, in __call__
    raise exc
  File "/usr/local/lib/python3.9/site-packages/starlette/middleware/errors.py", line 164, in __call__
    await self.app(scope, receive, _send)
  File "/usr/local/lib/python3.9/site-packages/starlette/middleware/cors.py", line 85, in __call__
    await self.app(scope, receive, send)
  File "/usr/local/lib/python3.9/site-packages/starlette/middleware/exceptions.py", line 65, in __call__
    await wrap_app_handling_exceptions(self.app, conn)(scope, receive, send)
  File "/usr/local/lib/python3.9/site-packages/starlette/_exception_handler.py", line 64, in wrapped_app
    raise exc
  File "/usr/local/lib/python3.9/site-packages/starlette/_exception_handler.py", line 53, in wrapped_app
    await app(scope, receive, sender)
  File "/usr/local/lib/python3.9/site-packages/starlette/routing.py", line 756, in __call__
    await self.middleware_stack(scope, receive, send)
  File "/usr/local/lib/python3.9/site-packages/starlette/routing.py", line 776, in app
    await route.handle(scope, receive, send)
  File "/usr/local/lib/python3.9/site-packages/starlette/routing.py", line 297, in handle
    await self.app(scope, receive, send)
  File "/usr/local/lib/python3.9/site-packages/starlette/routing.py", line 77, in app
    await wrap_app_handling_exceptions(app, request)(scope, receive, send)
  File "/usr/local/lib/python3.9/site-packages/starlette/_exception_handler.py", line 64, in wrapped_app
    raise exc
  File "/usr/local/lib/python3.9/site-packages/starlette/_exception_handler.py", line 53, in wrapped_app
    await app(scope, receive, sender)
  File "/usr/local/lib/python3.9/site-packages/starlette/routing.py", line 72, in app
    response = await func(request)
  File "/usr/local/lib/python3.9/site-packages/fastapi/routing.py", line 278, in app
    raw_response = await run_endpoint_function(
  File "/usr/local/lib/python3.9/site-packages/fastapi/routing.py", line 191, in run_endpoint_function
    return await dependant.call(**values)
  File "/app/./api/fast_api.py", line 230, in user_login_endpoint
    if auth_user(request_json) == False:
  File "/app/./api/fast_api.py", line 49, in auth_user
    mycursor.execute("SELECT pword FROM users WHERE email_address = %s", (email,))
  File "/usr/local/lib/python3.9/site-packages/mysql/connector/cursor_cext.py", line 374, in execute
    result = self._cnx.cmd_query(
  File "/usr/local/lib/python3.9/site-packages/mysql/connector/opentelemetry/context_propagation.py", line 74, in wrapper
    return method(cnx, *args, **kwargs)
  File "/usr/local/lib/python3.9/site-packages/mysql/connector/connection_cext.py", line 669, in cmd_query
    raise get_mysql_exception(
mysql.connector.errors.OperationalError: 2013 (HY000): Lost connection to MySQL server during query
ERROR:    Exception in ASGI application
Traceback (most recent call last):
  File "/usr/local/lib/python3.9/site-packages/mysql/connector/connection_cext.py", line 661, in cmd_query
    self._cmysql.query(
_mysql_connector.MySQLInterfaceError: Lost connection to MySQL server during query

The above exception was the direct cause of the following exception:

Traceback (most recent call last):
  File "/usr/local/lib/python3.9/site-packages/uvicorn/protocols/http/httptools_impl.py", line 419, in run_asgi
    result = await app(  # type: ignore[func-returns-value]
  File "/usr/local/lib/python3.9/site-packages/uvicorn/middleware/proxy_headers.py", line 78, in __call__
    return await self.app(scope, receive, send)
  File "/usr/local/lib/python3.9/site-packages/fastapi/applications.py", line 1054, in __call__
    await super().__call__(scope, receive, send)
  File "/usr/local/lib/python3.9/site-packages/starlette/applications.py", line 123, in __call__
    await self.middleware_stack(scope, receive, send)
  File "/usr/local/lib/python3.9/site-packages/starlette/middleware/errors.py", line 186, in __call__
    raise exc
  File "/usr/local/lib/python3.9/site-packages/starlette/middleware/errors.py", line 164, in __call__
    await self.app(scope, receive, _send)
  File "/usr/local/lib/python3.9/site-packages/starlette/middleware/cors.py", line 85, in __call__
    await self.app(scope, receive, send)
  File "/usr/local/lib/python3.9/site-packages/starlette/middleware/exceptions.py", line 65, in __call__
    await wrap_app_handling_exceptions(self.app, conn)(scope, receive, send)
  File "/usr/local/lib/python3.9/site-packages/starlette/_exception_handler.py", line 64, in wrapped_app
    raise exc
  File "/usr/local/lib/python3.9/site-packages/starlette/_exception_handler.py", line 53, in wrapped_app
    await app(scope, receive, sender)
  File "/usr/local/lib/python3.9/site-packages/starlette/routing.py", line 756, in __call__
    await self.middleware_stack(scope, receive, send)
  File "/usr/local/lib/python3.9/site-packages/starlette/routing.py", line 776, in app
    await route.handle(scope, receive, send)
  File "/usr/local/lib/python3.9/site-packages/starlette/routing.py", line 297, in handle
    await self.app(scope, receive, send)
  File "/usr/local/lib/python3.9/site-packages/starlette/routing.py", line 77, in app
    await wrap_app_handling_exceptions(app, request)(scope, receive, send)
  File "/usr/local/lib/python3.9/site-packages/starlette/_exception_handler.py", line 64, in wrapped_app
    raise exc
  File "/usr/local/lib/python3.9/site-packages/starlette/_exception_handler.py", line 53, in wrapped_app
    await app(scope, receive, sender)
  File "/usr/local/lib/python3.9/site-packages/starlette/routing.py", line 72, in app
    response = await func(request)
  File "/usr/local/lib/python3.9/site-packages/fastapi/routing.py", line 278, in app
    raw_response = await run_endpoint_function(
  File "/usr/local/lib/python3.9/site-packages/fastapi/routing.py", line 191, in run_endpoint_function
    return await dependant.call(**values)
  File "/app/./api/fast_api.py", line 230, in user_login_endpoint
    if auth_user(request_json) == False:
  File "/app/./api/fast_api.py", line 49, in auth_user
    mycursor.execute("SELECT pword FROM users WHERE email_address = %s", (email,))
  File "/usr/local/lib/python3.9/site-packages/mysql/connector/cursor_cext.py", line 374, in execute
    result = self._cnx.cmd_query(
  File "/usr/local/lib/python3.9/site-packages/mysql/connector/opentelemetry/context_propagation.py", line 74, in wrapper
    return method(cnx, *args, **kwargs)
  File "/usr/local/lib/python3.9/site-packages/mysql/connector/connection_cext.py", line 669, in cmd_query
    raise get_mysql_exception(
mysql.connector.errors.OperationalError: 2013 (HY000): Lost connection to MySQL server during query